<?xml version="1.0" ?><!-- =================================================================================== --><!-- |    This document was autogenerated by xacro from /home/juddbe/rover_ws/src/rover/install/rover/share/rover/models/my_robot.urdf.xacro | --><!-- |    EDITING THIS FILE BY HAND IS NOT RECOMMENDED                                 | --><!-- =================================================================================== --><robot name="my_robot"><material name="grey"><color rgba="0.5 0.5 0.5 1"/></material><material name="blue"><color rgba="0 0 0.6 1"/></material><material name="white"><color rgba="1 1 1 1"/></material><gazebo reference="base_link"><mu1>0.2</mu1><mu2>0.2</mu2><material>Gazebo/Blue</material></gazebo><gazebo reference="stand_link"><mu1>0.2</mu1><mu2>0.2</mu2><material>Gazebo/Blue</material></gazebo><gazebo reference="camera_l_link"><mu1>0.2</mu1><mu2>0.2</mu2><material>Gazebo/White</material></gazebo><gazebo reference="camera_r_link"><mu1>0.2</mu1><mu2>0.2</mu2><material>Gazebo/White</material></gazebo><gazebo reference="wheel_fr_link"><mu1>0.2</mu1><mu2>0.2</mu2><material>Gazebo/White</material></gazebo><gazebo reference="wheel_fl_link"><mu1>0.2</mu1><mu2>0.2</mu2><material>Gazebo/White</material></gazebo><gazebo reference="wheel_br_link"><mu1>0.2</mu1><mu2>0.2</mu2><material>Gazebo/White</material></gazebo><gazebo reference="wheel_bl_link"><mu1>0.2</mu1><mu2>0.2</mu2><material>Gazebo/White</material></gazebo><gazebo><!-- <plugin filename="gz-sim-physics-system" name="gz::sim::systems::Physics"></plugin>
        <plugin filename="gz-sim-scene-broadcaster-system" name="gz::sim::systems::SceneBroadcaster"></plugin> --><!-- <plugin filename="gz_ros2_control-system" name="gz_ros2_control::GazeboSimROS2ControlPlugin">
            <parameters>$(find rover)/config/gz_bridge.yaml</parameters>
        </plugin> --><plugin filename="gz-sim-imu-system" name="gz::sim::systems::Imu"/><plugin filename="gz-sim-sensors-system" name="gz::sim::systems::Sensors"><render_engine>ogre2</render_engine></plugin><gazebo reference="lidar_link"><sensor name="lidar_link" type="gpu_lidar"><gz_frame_id>lidar_link</gz_frame_id><topic>scan</topic><update_rate>30</update_rate><lidar><scan><horizontal><samples>2800</samples><resolution>1</resolution><min_angle>-3.14</min_angle><max_angle>3.14</max_angle></horizontal><vertical><samples>1</samples><resolution>0.1</resolution><min_angle>0</min_angle><max_angle>0</max_angle></vertical></scan><range><min>0.1</min><max>30.0</max><resolution>0.01</resolution></range><frame_id>/lidar_link</frame_id></lidar><alwaysOn>true</alwaysOn><visualize>true</visualize></sensor></gazebo><!-- <plugin filename="gz-sim-diff-drive-system" name="gz::sim::systems::DiffDrive">
            <left_joint>wheel_fl_joint</left_joint>
            <left_joint>wheel_bl_joint</left_joint>
            <right_joint>wheel_fr_joint</right_joint>
            <right_joint>wheel_br_joint</right_joint>
            <wheel_separation>0.7</wheel_separation>
            <wheel_radius>0.2</wheel_radius>
            <max_linear_acceleration>10</max_linear_acceleration>
            <odom_publish_frequency>100</odom_publish_frequency>
            <topic>cmd_vel</topic>
            <odom_topic>odom</odom_topic>
        </plugin> --></gazebo><joint name="stand_joint" type="fixed"><origin xyz="0.2857142857142857 0 0.7100000000000001"/><parent link="base_link"/><child link="stand_link"/></joint><!-- <joint name="camera_l_joint" type="fixed">
        <origin xyz="${stand_length/2} ${stand_width/3} ${stand_height/2 - camera_height/2}"/>
        <parent link="stand_link"/>
        <child link="camera_l_link"/>
    </joint>

    <joint name="camera_r_joint" type="fixed">
        <origin xyz="${stand_length/2} ${-stand_width/3} ${stand_height/2 - camera_height/2}"/>
        <parent link="stand_link"/>
        <child link="camera_r_link"/>
    </joint> --><joint name="lidar_joint" type="fixed"><origin xyz="0 0 0.2"/><parent link="stand_link"/><child link="lidar_link"/></joint><joint name="wheel_fr_joint" type="continuous"><parent link="base_link"/><child link="wheel_fr_link"/><axis xyz="0 1 0"/><origin rpy="0 0 0" xyz="0.2857142857142857 -0.35 0.2"/><limit effort="20000" velocity="1"/><dynamics damping="1.0" friction="1.0"/></joint><joint name="wheel_fl_joint" type="continuous"><parent link="base_link"/><child link="wheel_fl_link"/><axis xyz="0 1 0"/><origin rpy="0 0 0" xyz="0.2857142857142857 0.35 0.2"/><limit effort="20000" velocity="1"/><dynamics damping="1.0" friction="1.0"/></joint><joint name="wheel_br_joint" type="continuous"><parent link="base_link"/><child link="wheel_br_link"/><axis xyz="0 1 0"/><origin rpy="0 0 0" xyz="-0.2857142857142857 -0.35 0.2"/><limit effort="20000" velocity="1"/><dynamics damping="1.0" friction="1.0"/></joint><joint name="wheel_bl_joint" type="continuous"><parent link="base_link"/><child link="wheel_bl_link"/><axis xyz="0 1 0"/><origin rpy="0 0 0" xyz="-0.2857142857142857 0.35 0.2"/><limit effort="20000" velocity="1"/><dynamics damping="1.0" friction="1.0"/></joint><link name="base_link"><visual><geometry><box size="1 0.6 0.4"/></geometry><origin rpy="0 0 0" xyz="0 0 0.36000000000000004"/><material name="blue"/></visual><collision><geometry><box size="1 0.6 0.4"/></geometry><origin rpy="0 0 0" xyz="0 0 0.36000000000000004"/></collision><inertial><origin rpy="0 0 0" xyz="0 0 0.36000000000000004"/><mass value="10"/><inertia ixx="0.9666666666666668" ixy="0" ixz="0" iyy="0.43333333333333335" iyz="0" izz="1.1333333333333333"/></inertial></link><link name="stand_link"><visual><geometry><box size="0.15 0.45 0.3"/></geometry><origin rpy="0 0 0" xyz="0 0 0"/><material name="blue"/></visual><collision><geometry><box size="0.15 0.45 0.3"/></geometry><origin rpy="0 0 0" xyz="0 0 0"/></collision><inertial><origin rpy="0 0 0" xyz="0 0 0"/><mass value="3"/><inertia ixx="0.028124999999999997" ixy="0" ixz="0" iyy="0.073125" iyz="0" izz="0.05625"/></inertial></link><!-- <link name="camera_l_link">
        <visual>
            <geometry>
                <box size="${camera_length/2} ${camera_width} ${camera_height}"/>
            </geometry>
            <origin xyz="${-camera_length/4 + camera_length/2} 0 0" rpy="0 0 0"/>
            <material name="white"/>
        </visual>
        <visual>
            <geometry>
                <cylinder radius="${camera_width/3.2}" length="${camera_length/2}"/>
            </geometry>
            <origin xyz="${camera_length/4 + camera_length/2} 0 0" rpy="0 ${pi/2} 0"/>
            <material name="white"/>
        </visual>
        <collision>
            <geometry>
                <box size="${camera_length} ${camera_width} ${camera_height}"/>
            </geometry>
            <origin xyz="0 0 0" rpy="0 0 0"/>
        </collision>
        <inertial>
            <origin xyz="0 0 0" rpy="0 0 0"/>
            <mass value="${camera_mass}"/>
            <inertia ixx="${(camera_mass/12)*(camera_height * camera_height + camera_length * camera_length)}" ixy="0" ixz="0" iyy="${(camera_mass/12)*(camera_height * camera_height + camera_width * camera_width)}" iyz="0" izz="${(camera_mass/12)*(camera_length * camera_length + camera_width * camera_width)}"/>
        </inertial>
    </link>

    <link name="camera_r_link">
        <visual>
            <geometry>
                <box size="${camera_length/2} ${camera_width} ${camera_height}"/>
            </geometry>
            <origin xyz="${-camera_length/4 + camera_length/2} 0 0" rpy="0 0 0"/>
            <material name="white"/>
        </visual>
        <visual>
            <geometry>
                <cylinder radius="${camera_width/3.2}" length="${camera_length/2}"/>
            </geometry>
            <origin xyz="${camera_length/4 + camera_length/2} 0 0" rpy="0 ${pi/2} 0"/>
            <material name="white"/>
        </visual>
        <collision>
            <geometry>
                <box size="${camera_length} ${camera_width} ${camera_height}"/>
            </geometry>
            <origin xyz="0 0 0" rpy="0 0 0"/>
        </collision>
        <inertial>
            <origin xyz="0 0 0" rpy="0 0 0"/>
            <mass value="${camera_mass}"/>
            <inertia ixx="${(camera_mass/12)*(camera_height * camera_height + camera_length * camera_length)}" ixy="0" ixz="0" iyy="${(camera_mass/12)*(camera_height * camera_height + camera_width * camera_width)}" iyz="0" izz="${(camera_mass/12)*(camera_length * camera_length + camera_width * camera_width)}"/>
        </inertial>
    </link> --><link name="lidar_link"><visual><geometry><cylinder length="0.1" radius="0.05"/></geometry><origin rpy="0 0 0" xyz="0 0 0"/><material name="white"/></visual><collision><geometry><cylinder length="0.1" radius="0.05"/></geometry><origin rpy="0 0 0" xyz="0 0 0"/></collision><inertial><origin rpy="0 0 0" xyz="0 0 0"/><mass value="0.1"/><inertia ixx="0.00014583333333333335" ixy="0" ixz="0" iyy="0.00014583333333333335" iyz="0" izz="0.00012500000000000003"/></inertial></link><link name="wheel_fr_link"><visual><geometry><cylinder length="0.1" radius="0.2"/></geometry><origin rpy="1.5707963267948966 0 0" xyz="0 0 0"/><material name="grey"/></visual><collision><geometry><cylinder length="0.1" radius="0.2"/></geometry><origin rpy="1.5707963267948966 0 0" xyz="0 0 0"/></collision><inertial><origin rpy="1.5707963267948966 0 0" xyz="0 0 0"/><mass value="2.5"/><inertia ixx="0.02708333333333334" ixy="0" ixz="0" iyy="0.02708333333333334" iyz="0" izz="0.05"/></inertial></link><link name="wheel_fl_link"><visual><geometry><cylinder length="0.1" radius="0.2"/></geometry><origin rpy="1.5707963267948966 0 0" xyz="0 0 0"/><material name="grey"/></visual><collision><geometry><cylinder length="0.1" radius="0.2"/></geometry><origin rpy="1.5707963267948966 0 0" xyz="0 0 0"/></collision><inertial><origin rpy="1.5707963267948966 0 0" xyz="0 0 0"/><mass value="2.5"/><inertia ixx="0.02708333333333334" ixy="0" ixz="0" iyy="0.02708333333333334" iyz="0" izz="0.05"/></inertial></link><link name="wheel_br_link"><visual><geometry><cylinder length="0.1" radius="0.2"/></geometry><origin rpy="1.5707963267948966 0 0" xyz="0 0 0"/><material name="grey"/></visual><collision><geometry><cylinder length="0.1" radius="0.2"/></geometry><origin rpy="1.5707963267948966 0 0" xyz="0 0 0"/></collision><inertial><origin rpy="1.5707963267948966 0 0" xyz="0 0 0"/><mass value="2.5"/><inertia ixx="0.02708333333333334" ixy="0" ixz="0" iyy="0.02708333333333334" iyz="0" izz="0.05"/></inertial></link><link name="wheel_bl_link"><visual><geometry><cylinder length="0.1" radius="0.2"/></geometry><origin rpy="1.5707963267948966 0 0" xyz="0 0 0"/><material name="grey"/></visual><collision><geometry><cylinder length="0.1" radius="0.2"/></geometry><origin rpy="1.5707963267948966 0 0" xyz="0 0 0"/></collision><inertial><origin rpy="1.5707963267948966 0 0" xyz="0 0 0"/><mass value="2.5"/><inertia ixx="0.02708333333333334" ixy="0" ixz="0" iyy="0.02708333333333334" iyz="0" izz="0.05"/></inertial></link></robot>