<?xml version="1.0" ?><!-- =================================================================================== --><!-- |    This document was autogenerated by xacro from /home/juddbe/AutoRover/install/rover/share/rover/models/my_robot.urdf.xacro | --><!-- |    EDITING THIS FILE BY HAND IS NOT RECOMMENDED                                 | --><!-- =================================================================================== --><robot name="rover"><material name="grey"><color rgba="0.5 0.5 0.5 1"/></material><material name="pink"><color rgba="0.96 0.76 0.76 1"/></material><material name="white"><color rgba="1 1 1 1"/></material><gazebo reference="base_link"><mu1>0.2</mu1><mu2>0.2</mu2><material>Gazebo/Blue</material></gazebo><gazebo reference="stand_link"><mu1>0.2</mu1><mu2>0.2</mu2><material>Gazebo/Blue</material></gazebo><gazebo reference="camera_l_link"><mu1>0.2</mu1><mu2>0.2</mu2><material>Gazebo/White</material></gazebo><gazebo reference="camera_r_link"><mu1>0.2</mu1><mu2>0.2</mu2><material>Gazebo/White</material></gazebo><gazebo reference="wheel_fr_link"><mu1>1.0</mu1><mu2>0.2</mu2><fdir1>1 0 0</fdir1><material>Gazebo/White</material></gazebo><gazebo reference="wheel_fl_link"><mu1>1.0</mu1><mu2>0.2</mu2><fdir1>1 0 0</fdir1><material>Gazebo/White</material></gazebo><gazebo reference="wheel_br_link"><mu1>1.0</mu1><mu2>0.2</mu2><fdir1>1 0 0</fdir1><material>Gazebo/White</material></gazebo><gazebo reference="wheel_bl_link"><mu1>1.0</mu1><mu2>0.2</mu2><fdir1>1 0 0</fdir1><material>Gazebo/White</material></gazebo><gazebo><plugin filename="gz-sim-imu-system" name="gz::sim::systems::Imu">
    
        </plugin><plugin filename="gz-sim-sensors-system" name="gz::sim::systems::Sensors"><render_engine>ogre2</render_engine></plugin><plugin filename="gz-sim-diff-drive-system" name="gz::sim::systems::DiffDrive"><!-- wheels --><num_wheel_pairs>2</num_wheel_pairs><left_joint>wheel_fl_joint</left_joint><left_joint>wheel_bl_joint</left_joint><right_joint>wheel_fr_joint</right_joint><right_joint>wheel_br_joint</right_joint><!-- kinematics --><wheel_separation>0.7</wheel_separation><wheel_radius>0.2</wheel_radius><!-- 4/7 m --><wheelbase>0.57142857</wheelbase><!-- limits --><max_linear_acceleration>10</max_linear_acceleration><max_velocity>10.0</max_velocity><max_angular_velocity>10.0</max_angular_velocity><!-- topics, update frequencies --><update_rate>100</update_rate><odom_publish_frequency>100</odom_publish_frequency><topic>cmd_vel</topic><tf_topic>/tf</tf_topic><odom_topic>odom</odom_topic></plugin><plugin filename="gz-sim-joint-state-publisher-system" name="gz::sim::systems::JointStatePublisher"><topic>joint_states</topic><joint_name>wheel_fl_joint</joint_name><joint_name>wheel_bl_joint</joint_name><joint_name>wheel_fr_joint</joint_name><joint_name>wheel_br_joint</joint_name></plugin></gazebo><gazebo reference="imu_link"><sensor name="imu" type="imu"><always_on>1</always_on><update_rate>100</update_rate><visualize>true</visualize><topic>imu</topic></sensor></gazebo><gazebo reference="lidar_link"><sensor name="lidar" type="gpu_lidar"><pose>0 0 0 0 0 0</pose><topic>cloud</topic><update_rate>10</update_rate><gz_frame_id>lidar_link</gz_frame_id><lidar><scan><horizontal><samples>720</samples><min_angle>-3.141592653</min_angle><max_angle>3.141592653</max_angle></horizontal><vertical><samples>96</samples><min_angle>-0.61</min_angle><max_angle>-0.001</max_angle></vertical></scan><range><min>0.3</min><max>8.5</max><resolution>0.01</resolution><noise><type>gaussian</type><mean>0.0</mean><stddev>0.02</stddev></noise></range></lidar><always_on>1</always_on><visualize>true</visualize></sensor></gazebo><joint name="stand_joint" type="fixed"><origin xyz="0 0 0.7100000000000001"/><parent link="base_link"/><child link="stand_link"/></joint><joint name="lidar_joint" type="fixed"><origin xyz="0 0 0.2"/><parent link="stand_link"/><child link="lidar_link"/></joint><joint name="imu_joint" type="fixed"><parent link="base_link"/><child link="imu_link"/></joint><joint name="wheel_fr_joint" type="continuous"><parent link="base_link"/><child link="wheel_fr_link"/><axis xyz="0 1 0"/><origin rpy="0 0 0" xyz="0.2285714285714286 -0.35 0.2"/><limit effort="2000" velocity="1.0"/></joint><joint name="wheel_fl_joint" type="continuous"><parent link="base_link"/><child link="wheel_fl_link"/><axis xyz="0 1 0"/><origin rpy="0 0 0" xyz="0.2285714285714286 0.35 0.2"/><limit effort="2000" velocity="1.0"/></joint><joint name="wheel_br_joint" type="continuous"><parent link="base_link"/><child link="wheel_br_link"/><axis xyz="0 1 0"/><origin rpy="0 0 0" xyz="-0.2285714285714286 -0.35 0.2"/><limit effort="2000" velocity="1.0"/></joint><joint name="wheel_bl_joint" type="continuous"><parent link="base_link"/><child link="wheel_bl_link"/><axis xyz="0 1 0"/><origin rpy="0 0 0" xyz="-0.2285714285714286 0.35 0.2"/><limit effort="2000" velocity="1.0"/></joint><link name="base_link"><visual><geometry><box size="0.8 0.6 0.4"/></geometry><origin rpy="0 0 0" xyz="0 0 0.36000000000000004"/><material name="pink"/></visual><collision><geometry><box size="0.8 0.6 0.4"/></geometry><origin rpy="0 0 0" xyz="0 0 0.36000000000000004"/></collision><inertial><origin rpy="0 0 0" xyz="0 0 0.36000000000000004"/><mass value="5"/><inertia ixx="0.3333333333333334" ixy="0" ixz="0" iyy="0.21666666666666667" iyz="0" izz="0.4166666666666667"/></inertial></link><link name="stand_link"><visual><geometry><box size="0.15 0.1 0.3"/></geometry><origin rpy="0 0 0" xyz="0 0 0"/><material name="pink"/></visual><collision><geometry><box size="0.15 0.1 0.3"/></geometry><origin rpy="0 0 0" xyz="0 0 0"/></collision><inertial><origin rpy="0 0 0" xyz="0 0 0"/><mass value="1"/><inertia ixx="0.009374999999999998" ixy="0" ixz="0" iyy="0.008333333333333333" iyz="0" izz="0.0027083333333333334"/></inertial></link><link name="lidar_link"><visual><geometry><cylinder length="0.1" radius="0.05"/></geometry><origin rpy="0 0 0" xyz="0 0 0"/><material name="white"/></visual><collision><geometry><cylinder length="0.1" radius="0.05"/></geometry><origin rpy="0 0 0" xyz="0 0 0"/></collision><inertial><origin rpy="0 0 0" xyz="0 0 0"/><mass value="0.1"/><inertia ixx="0.00014583333333333335" ixy="0" ixz="0" iyy="0.00014583333333333335" iyz="0" izz="0.00012500000000000003"/></inertial></link><link name="imu_link"><inertial><mass value="0.01"/><origin rpy="0 0 0" xyz="0 0 0"/><inertia ixx="1e-5" ixy="0" ixz="0" iyy="1e-5" iyz="0" izz="1e-5"/></inertial></link><link name="wheel_fr_link"><visual><geometry><cylinder length="0.1" radius="0.2"/></geometry><origin rpy="1.5707963267948966 0 0" xyz="0 0 0"/><material name="grey"/></visual><collision><geometry><cylinder length="0.1" radius="0.2"/></geometry><origin rpy="1.5707963267948966 0 0" xyz="0 0 0"/></collision><inertial><origin rpy="1.5707963267948966 0 0" xyz="0 0 0"/><mass value="1.2"/><inertia ixx="0.013000000000000003" ixy="0" ixz="0" iyy="0.013000000000000003" iyz="0" izz="0.024"/></inertial></link><link name="wheel_fl_link"><visual><geometry><cylinder length="0.1" radius="0.2"/></geometry><origin rpy="1.5707963267948966 0 0" xyz="0 0 0"/><material name="grey"/></visual><collision><geometry><cylinder length="0.1" radius="0.2"/></geometry><origin rpy="1.5707963267948966 0 0" xyz="0 0 0"/></collision><inertial><origin rpy="1.5707963267948966 0 0" xyz="0 0 0"/><mass value="1.2"/><inertia ixx="0.013000000000000003" ixy="0" ixz="0" iyy="0.013000000000000003" iyz="0" izz="0.024"/></inertial></link><link name="wheel_br_link"><visual><geometry><cylinder length="0.1" radius="0.2"/></geometry><origin rpy="1.5707963267948966 0 0" xyz="0 0 0"/><material name="grey"/></visual><collision><geometry><cylinder length="0.1" radius="0.2"/></geometry><origin rpy="1.5707963267948966 0 0" xyz="0 0 0"/></collision><inertial><origin rpy="1.5707963267948966 0 0" xyz="0 0 0"/><mass value="1.2"/><inertia ixx="0.013000000000000003" ixy="0" ixz="0" iyy="0.013000000000000003" iyz="0" izz="0.024"/></inertial></link><link name="wheel_bl_link"><visual><geometry><cylinder length="0.1" radius="0.2"/></geometry><origin rpy="1.5707963267948966 0 0" xyz="0 0 0"/><material name="grey"/></visual><collision><geometry><cylinder length="0.1" radius="0.2"/></geometry><origin rpy="1.5707963267948966 0 0" xyz="0 0 0"/></collision><inertial><origin rpy="1.5707963267948966 0 0" xyz="0 0 0"/><mass value="1.2"/><inertia ixx="0.013000000000000003" ixy="0" ixz="0" iyy="0.013000000000000003" iyz="0" izz="0.024"/></inertial></link></robot>