<sdf version='1.10'>
  <world name='rover'>
    <physics name='1ms' type='ode'>
      <max_step_size>0.001</max_step_size>
      <real_time_factor>1</real_time_factor>
      <real_time_update_rate>1000</real_time_update_rate>
      <solver>
        <type>quickstep</type>
        <iters>100</iters>
      </solver>
    </physics>
    <plugin name='gz::sim::systems::Physics' filename='gz-sim-physics-system'/>
    <plugin name='gz::sim::systems::UserCommands' filename='gz-sim-user-commands-system'/>
    <plugin name='gz::sim::systems::SceneBroadcaster' filename='gz-sim-scene-broadcaster-system'/>
    <plugin name='gz::sim::systems::Contact' filename='gz-sim-contact-system'/>
    <gravity>0 0 -9.8000000000000007</gravity>
    <magnetic_field>5.5644999999999998e-06 2.2875799999999999e-05 -4.2388400000000002e-05</magnetic_field>
    <atmosphere type='adiabatic'/>
    <scene>
      <ambient>0.400000006 0.400000006 0.400000006 1</ambient>
      <background>0.699999988 0.699999988 0.699999988 1</background>
      <shadows>true</shadows>
    </scene>
    <model name='ground_plane'>
      <static>true</static>
      <link name='link'>
        <collision name='collision'>
          <geometry>
            <plane>
              <normal>0 0 1</normal>
              <size>100 100</size>
            </plane>
          </geometry>
          <surface>
            <friction>
              <ode>
                <mu>1.0</mu>  <!-- Forward friction -->
                <mu2>1.0</mu2>  <!-- Lateral friction -->
              </ode>
            </friction>
            <bounce/>
            <contact/>
          </surface>
        </collision>
        <visual name='visual'>
          <geometry>
            <plane>
              <normal>0 0 1</normal>
              <size>100 100</size>
            </plane>
          </geometry>
          <material>
            <ambient>0.800000012 0.800000012 0.800000012 1</ambient>
            <diffuse>0.800000012 0.800000012 0.800000012 1</diffuse>
            <specular>0.800000012 0.800000012 0.800000012 1</specular>
          </material>
        </visual>
        <pose>0 0 0 0 0 0</pose>
        <enable_wind>false</enable_wind>
      </link>
      <pose>0 0 0 0 0 0</pose>
      <self_collide>false</self_collide>
    </model>
    <light name='sun' type='directional'>
      <pose>0 0 10 0 0 0</pose>
      <cast_shadows>true</cast_shadows>
      <intensity>1</intensity>
      <direction>-0.5 0.10000000000000001 -0.90000000000000002</direction>
      <diffuse>0.800000012 0.800000012 0.800000012 1</diffuse>
      <specular>0.200000003 0.200000003 0.200000003 1</specular>
      <attenuation>
        <range>1000</range>
        <linear>0.01</linear>
        <constant>0.90000000000000002</constant>
        <quadratic>0.001</quadratic>
      </attenuation>
      <spot>
        <inner_angle>0</inner_angle>
        <outer_angle>0</outer_angle>
        <falloff>0</falloff>
      </spot>
    </light>







    <model name='rover'>
      <link name='base_link'>
        <inertial>
          <pose>0 0 0.42569558101472998 0 0 0</pose>
          <mass>6.1099999999999994</mass>
          <inertia>
            <ixx>0.47053996044735391</ixx>
            <ixy>0</ixy>
            <ixz>0</ixz>
            <iyy>0.35283162711402061</iyy>
            <iyz>0</iyz>
            <izz>0.41950999999999999</izz>
          </inertia>
        </inertial>
        <collision name='base_link_collision'>
          <pose>0 0 0.35999999999999999 0 0 0</pose>
          <geometry>
            <box>
              <size>0.80000000000000004 0.59999999999999998 0.40000000000000002</size>
            </box>
          </geometry>
          <surface>
            <contact>
              <ode/>
            </contact>
            <friction>
              <ode>
                <mu>0.20000000000000001</mu>
                <mu2>0.20000000000000001</mu2>
              </ode>
            </friction>
          </surface>
        </collision>
        <collision name='base_link_fixed_joint_lump__stand_link_collision_1'>
          <pose>0 0 0.71000000000000008 0 0 0</pose>
          <geometry>
            <box>
              <size>0.14999999999999999 0.10000000000000001 0.29999999999999999</size>
            </box>
          </geometry>
          <surface>
            <contact>
              <ode/>
            </contact>
            <friction>
              <ode>
                <mu>0.20000000000000001</mu>
                <mu2>0.20000000000000001</mu2>
              </ode>
            </friction>
          </surface>
        </collision>
        <collision name='base_link_fixed_joint_lump__lidar_link_collision_2'>
          <pose>0 0 0.91000000000000014 0 0 0</pose>
          <geometry>
            <cylinder>
              <length>0.10000000000000001</length>
              <radius>0.050000000000000003</radius>
            </cylinder>
          </geometry>
          <surface>
            <contact>
              <ode/>
            </contact>
            <friction>
              <ode/>
            </friction>
          </surface>
        </collision>
        <visual name='base_link_visual'>
          <pose>0 0 0.35999999999999999 0 0 0</pose>
          <geometry>
            <box>
              <size>0.80000000000000004 0.59999999999999998 0.40000000000000002</size>
            </box>
          </geometry>
          <material>
            <script>
              <name>Gazebo/Blue</name>
              <uri>file://media/materials/scripts/gazebo.material</uri>
            </script>
            <diffuse>1 0.949999988 0.949999988 1</diffuse>
            <ambient>1 0.949999988 0.949999988 1</ambient>
          </material>
        </visual>
        <visual name='base_link_fixed_joint_lump__stand_link_visual_1'>
          <pose>0 0 0.71000000000000008 0 0 0</pose>
          <geometry>
            <box>
              <size>0.14999999999999999 0.10000000000000001 0.29999999999999999</size>
            </box>
          </geometry>
          <material>
            <script>
              <name>Gazebo/Blue</name>
              <uri>file://media/materials/scripts/gazebo.material</uri>
            </script>
            <diffuse>1 0.949999988 0.949999988 1</diffuse>
            <ambient>1 0.949999988 0.949999988 1</ambient>
          </material>
        </visual>
        <visual name='base_link_fixed_joint_lump__lidar_link_visual_2'>
          <pose>0 0 0.91000000000000014 0 0 0</pose>
          <geometry>
            <cylinder>
              <length>0.10000000000000001</length>
              <radius>0.050000000000000003</radius>
            </cylinder>
          </geometry>
          <material>
            <diffuse>1 1 1 1</diffuse>
            <ambient>1 1 1 1</ambient>
          </material>
        </visual>
        <sensor name='imu' type='imu'>
          <always_on>true</always_on>
          <update_rate>100</update_rate>
          <visualize>true</visualize>
          <topic>imu</topic>
          <pose>0 0 0 0 0 0</pose>
        </sensor>
        <sensor name='lidar' type='gpu_lidar'>
          <topic>cloud</topic>
          <update_rate>10</update_rate>
          <lidar>
            <scan>
              <horizontal>
                <samples>720</samples>
                <min_angle>-3.141592653</min_angle>
                <max_angle>3.141592653</max_angle>
                <resolution>1</resolution>
              </horizontal>
              <vertical>
                <samples>64</samples>
                <min_angle>-0.60999999999999999</min_angle>
                <max_angle>-0.001</max_angle>
              </vertical>
            </scan>
            <range>
              <min>0.29999999999999999</min>
              <max>8</max>
              <resolution>0.01</resolution>
              <noise>
                <type>gaussian</type>
                <mean>0.0</mean>
                <stddev>0.02</stddev>
              </noise>
            </range>
          </lidar>
          <always_on>true</always_on>
          <visualize>true</visualize>
          <pose>0 0 0.91000000000000003 0 0 0</pose>
          <gz_frame_id>lidar_link</gz_frame_id>
        </sensor>
      </link>
      <joint name='wheel_bl_joint' type='revolute'>
        <pose relative_to='base_link'>-0.22857142857142859 0.34999999999999998 0.20000000000000001 0 0 0</pose>
        <parent>base_link</parent>
        <child>wheel_bl_link</child>
        <axis>
          <xyz>0 1 0</xyz>
          <limit>
            <effort>2000</effort>
            <velocity>1</velocity>
            <lower>-inf</lower>
            <upper>inf</upper>
          </limit>
          <dynamics>
            <spring_reference>0</spring_reference>
            <spring_stiffness>0</spring_stiffness>
          </dynamics>
        </axis>
      </joint>
      <link name='wheel_bl_link'>
        <pose relative_to='wheel_bl_joint'>0 0 0 0 0 0</pose>
        <inertial>
          <pose>0 0 0 1.5707963267948959 0 0</pose>
          <mass>1.2</mass>
          <inertia>
            <ixx>0.012999999999999999</ixx>
            <ixy>0</ixy>
            <ixz>0</ixz>
            <iyy>0.012999999999999999</iyy>
            <iyz>0</iyz>
            <izz>0.024</izz>
          </inertia>
        </inertial>
        <collision name='wheel_bl_link_collision'>
          <pose>0 0 0 1.5707963267948959 0 0</pose>
          <geometry>
            <cylinder>
              <length>0.10000000000000001</length>
              <radius>0.20000000000000001</radius>
            </cylinder>
          </geometry>
          <surface>
            <contact>
              <ode/>
            </contact>
            <friction>
              <ode>
                <mu>1</mu>
                <mu2>0.20000000000000001</mu2>
                <fdir1>1 0 0</fdir1>
              </ode>
            </friction>
          </surface>
        </collision>
        <visual name='wheel_bl_link_visual'>
          <pose>0 0 0 1.5707963267948959 0 0</pose>
          <geometry>
            <cylinder>
              <length>0.10000000000000001</length>
              <radius>0.20000000000000001</radius>
            </cylinder>
          </geometry>
          <material>
            <script>
              <name>Gazebo/White</name>
              <uri>file://media/materials/scripts/gazebo.material</uri>
            </script>
            <diffuse>0.625 0.625 0.625 1</diffuse>
            <ambient>0.625 0.625 0.625 1</ambient>
          </material>
        </visual>
      </link>
      <joint name='wheel_br_joint' type='revolute'>
        <pose relative_to='base_link'>-0.22857142857142859 -0.34999999999999998 0.20000000000000001 0 0 0</pose>
        <parent>base_link</parent>
        <child>wheel_br_link</child>
        <axis>
          <xyz>0 1 0</xyz>
          <limit>
            <effort>2000</effort>
            <velocity>1</velocity>
            <lower>-inf</lower>
            <upper>inf</upper>
          </limit>
          <dynamics>
            <spring_reference>0</spring_reference>
            <spring_stiffness>0</spring_stiffness>
          </dynamics>
        </axis>
      </joint>
      <link name='wheel_br_link'>
        <pose relative_to='wheel_br_joint'>0 0 0 0 0 0</pose>
        <inertial>
          <pose>0 0 0 1.5707963267948959 0 0</pose>
          <mass>1.2</mass>
          <inertia>
            <ixx>0.012999999999999999</ixx>
            <ixy>0</ixy>
            <ixz>0</ixz>
            <iyy>0.012999999999999999</iyy>
            <iyz>0</iyz>
            <izz>0.024</izz>
          </inertia>
        </inertial>
        <collision name='wheel_br_link_collision'>
          <pose>0 0 0 1.5707963267948959 0 0</pose>
          <geometry>
            <cylinder>
              <length>0.10000000000000001</length>
              <radius>0.20000000000000001</radius>
            </cylinder>
          </geometry>
          <surface>
            <contact>
              <ode/>
            </contact>
            <friction>
              <ode>
                <mu>1</mu>
                <mu2>0.20000000000000001</mu2>
                <fdir1>1 0 0</fdir1>
              </ode>
            </friction>
          </surface>
        </collision>
        <visual name='wheel_br_link_visual'>
          <pose>0 0 0 1.5707963267948959 0 0</pose>
          <geometry>
            <cylinder>
              <length>0.10000000000000001</length>
              <radius>0.20000000000000001</radius>
            </cylinder>
          </geometry>
          <material>
            <script>
              <name>Gazebo/White</name>
              <uri>file://media/materials/scripts/gazebo.material</uri>
            </script>
            <diffuse>0.625 0.625 0.625 1</diffuse>
            <ambient>0.625 0.625 0.625 1</ambient>
          </material>
        </visual>
      </link>
      <joint name='wheel_fl_joint' type='revolute'>
        <pose relative_to='base_link'>0.22857142857142859 0.34999999999999998 0.20000000000000001 0 0 0</pose>
        <parent>base_link</parent>
        <child>wheel_fl_link</child>
        <axis>
          <xyz>0 1 0</xyz>
          <limit>
            <effort>2000</effort>
            <velocity>1</velocity>
            <lower>-inf</lower>
            <upper>inf</upper>
          </limit>
          <dynamics>
            <spring_reference>0</spring_reference>
            <spring_stiffness>0</spring_stiffness>
          </dynamics>
        </axis>
      </joint>
      <link name='wheel_fl_link'>
        <pose relative_to='wheel_fl_joint'>0 0 0 0 0 0</pose>
        <inertial>
          <pose>0 0 0 1.5707963267948959 0 0</pose>
          <mass>1.2</mass>
          <inertia>
            <ixx>0.012999999999999999</ixx>
            <ixy>0</ixy>
            <ixz>0</ixz>
            <iyy>0.012999999999999999</iyy>
            <iyz>0</iyz>
            <izz>0.024</izz>
          </inertia>
        </inertial>
        <collision name='wheel_fl_link_collision'>
          <pose>0 0 0 1.5707963267948959 0 0</pose>
          <geometry>
            <cylinder>
              <length>0.10000000000000001</length>
              <radius>0.20000000000000001</radius>
            </cylinder>
          </geometry>
          <surface>
            <contact>
              <ode/>
            </contact>
            <friction>
              <ode>
                <mu>1</mu>
                <mu2>0.20000000000000001</mu2>
                <fdir1>1 0 0</fdir1>
              </ode>
            </friction>
          </surface>
        </collision>
        <visual name='wheel_fl_link_visual'>
          <pose>0 0 0 1.5707963267948959 0 0</pose>
          <geometry>
            <cylinder>
              <length>0.10000000000000001</length>
              <radius>0.20000000000000001</radius>
            </cylinder>
          </geometry>
          <material>
            <script>
              <name>Gazebo/White</name>
              <uri>file://media/materials/scripts/gazebo.material</uri>
            </script>
            <diffuse>0.625 0.625 0.625 1</diffuse>
            <ambient>0.625 0.625 0.625 1</ambient>
          </material>
        </visual>
      </link>
      <joint name='wheel_fr_joint' type='revolute'>
        <pose relative_to='base_link'>0.22857142857142859 -0.34999999999999998 0.20000000000000001 0 0 0</pose>
        <parent>base_link</parent>
        <child>wheel_fr_link</child>
        <axis>
          <xyz>0 1 0</xyz>
          <limit>
            <effort>2000</effort>
            <velocity>1</velocity>
            <lower>-inf</lower>
            <upper>inf</upper>
          </limit>
          <dynamics>
            <spring_reference>0</spring_reference>
            <spring_stiffness>0</spring_stiffness>
          </dynamics>
        </axis>
      </joint>
      <link name='wheel_fr_link'>
        <pose relative_to='wheel_fr_joint'>0 0 0 0 0 0</pose>
        <inertial>
          <pose>0 0 0 1.5707963267948959 0 0</pose>
          <mass>1.2</mass>
          <inertia>
            <ixx>0.012999999999999999</ixx>
            <ixy>0</ixy>
            <ixz>0</ixz>
            <iyy>0.012999999999999999</iyy>
            <iyz>0</iyz>
            <izz>0.024</izz>
          </inertia>
        </inertial>
        <collision name='wheel_fr_link_collision'>
          <pose>0 0 0 1.5707963267948959 0 0</pose>
          <geometry>
            <cylinder>
              <length>0.10000000000000001</length>
              <radius>0.20000000000000001</radius>
            </cylinder>
          </geometry>
          <surface>
            <contact>
              <ode/>
            </contact>
            <friction>
              <ode>
                <mu>1</mu>
                <mu2>0.20000000000000001</mu2>
                <fdir1>1 0 0</fdir1>
              </ode>
            </friction>
          </surface>
        </collision>
        <visual name='wheel_fr_link_visual'>
          <pose>0 0 0 1.5707963267948959 0 0</pose>
          <geometry>
            <cylinder>
              <length>0.10000000000000001</length>
              <radius>0.20000000000000001</radius>
            </cylinder>
          </geometry>
          <material>
            <script>
              <name>Gazebo/White</name>
              <uri>file://media/materials/scripts/gazebo.material</uri>
            </script>
            <diffuse>0.625 0.625 0.625 1</diffuse>
            <ambient>0.625 0.625 0.625 1</ambient>
          </material>
        </visual>
      </link>
      <plugin name='gz::sim::systems::Imu' filename='gz-sim-imu-system'/>
      <plugin name='gz::sim::systems::Sensors' filename='gz-sim-sensors-system'>
        <render_engine>ogre2</render_engine>
      </plugin>
      <plugin name='gz::sim::systems::DiffDrive' filename='gz-sim-diff-drive-system'>
        <num_wheel_pairs>2</num_wheel_pairs>
        <left_joint>wheel_fl_joint</left_joint>
        <left_joint>wheel_bl_joint</left_joint>
        <right_joint>wheel_fr_joint</right_joint>
        <right_joint>wheel_br_joint</right_joint>
        <wheel_separation>0.7</wheel_separation>
        <wheel_radius>0.2</wheel_radius>
        <wheelbase>0.57142857</wheelbase>
        <max_linear_acceleration>10</max_linear_acceleration>
        <max_velocity>10.0</max_velocity>
        <max_angular_velocity>10.0</max_angular_velocity>
        <update_rate>100</update_rate>
        <odom_publish_frequency>100</odom_publish_frequency>
        <topic>cmd_vel</topic>
        <tf_topic>/tf</tf_topic>
        <odom_topic>odom</odom_topic>
      </plugin>
      <plugin name='gz::sim::systems::JointStatePublisher' filename='gz-sim-joint-state-publisher-system'>
        <topic>joint_states</topic>
        <joint_name>wheel_fl_joint</joint_name>
        <joint_name>wheel_bl_joint</joint_name>
        <joint_name>wheel_fr_joint</joint_name>
        <joint_name>wheel_br_joint</joint_name>
      </plugin>
      <frame name='imu_joint' attached_to='base_link'>
        <pose>0 0 0 0 0 0</pose>
      </frame>
      <frame name='imu_link' attached_to='imu_joint'>
        <pose>0 0 0 0 0 0</pose>
      </frame>
      <frame name='lidar_joint' attached_to='stand_link'>
        <pose>0 0 0.20000000000000001 0 0 0</pose>
      </frame>
      <frame name='lidar_link' attached_to='lidar_joint'>
        <pose>0 0 0 0 0 0</pose>
      </frame>
      <frame name='stand_joint' attached_to='base_link'>
        <pose>0 0 0.71000000000000008 0 0 0</pose>
      </frame>
      <frame name='stand_link' attached_to='stand_joint'>
        <pose>0 0 0 0 0 0</pose>
      </frame>
    </model>

  </world>
</sdf>
